[INFO] [1752203019.489208483] [depth_integration_test]: 🧪 深度集成测试启动
[INFO] [1752203021.494329413] [depth_integration_test]: 🚀 开始深度查询测试...
[INFO] [1752203021.496887790] [depth_integration_test]: 📍 测试点 1: (320, 240)
[INFO] [1752203022.000768725] [depth_integration_test]: 📍 测试点 2: (160, 120)
[INFO] [1752203022.504616916] [depth_integration_test]: 📍 测试点 3: (480, 360)
[INFO] [1752203023.008412758] [depth_integration_test]: 📍 测试点 4: (100, 200)
[INFO] [1752203023.510964727] [depth_integration_test]: 📍 测试点 5: (500, 300)
[INFO] [1752203026.016067191] [depth_integration_test]: 📊 测试总结:
[INFO] [1752203026.018233489] [depth_integration_test]:    总查询数: 5
[INFO] [1752203026.019962211] [depth_integration_test]:    收到结果: 0
[INFO] [1752203026.021629671] [depth_integration_test]:    有效结果: 0
[INFO] [1752203026.023276128] [depth_integration_test]: 🔍 测试区域查询功能...
[INFO] [1752203027.028624264] [depth_integration_test]: 📈 测试统计查询功能...
[INFO] [1752203028.032955713] [depth_integration_test]: 🎉 所有测试完成！
Traceback (most recent call last):
  File "/userdata/try_again/SelfFollowingROS2/test_depth_integration.py", line 172, in main
    rclpy.spin_once(test_node, timeout_sec=0.1)
  File "/opt/ros/humble/local/lib/python3.10/dist-packages/rclpy/__init__.py", line 206, in spin_once
    executor.spin_once(timeout_sec=timeout_sec)
  File "/opt/ros/humble/local/lib/python3.10/dist-packages/rclpy/executors.py", line 751, in spin_once
    self._spin_once_impl(timeout_sec)
  File "/opt/ros/humble/local/lib/python3.10/dist-packages/rclpy/executors.py", line 740, in _spin_once_impl
    handler, entity, node = self.wait_for_ready_callbacks(timeout_sec=timeout_sec)
  File "/opt/ros/humble/local/lib/python3.10/dist-packages/rclpy/executors.py", line 723, in wait_for_ready_callbacks
    return next(self._cb_iter)
  File "/opt/ros/humble/local/lib/python3.10/dist-packages/rclpy/executors.py", line 624, in _wait_for_ready_callbacks
    raise ExternalShutdownException()
rclpy.executors.ExternalShutdownException

During handling of the above exception, another exception occurred:

Traceback (most recent call last):
  File "/userdata/try_again/SelfFollowingROS2/test_depth_integration.py", line 183, in <module>
    main()
  File "/userdata/try_again/SelfFollowingROS2/test_depth_integration.py", line 179, in main
    rclpy.shutdown()
  File "/opt/ros/humble/local/lib/python3.10/dist-packages/rclpy/__init__.py", line 130, in shutdown
    _shutdown(context=context)
  File "/opt/ros/humble/local/lib/python3.10/dist-packages/rclpy/utilities.py", line 58, in shutdown
    return context.shutdown()
  File "/opt/ros/humble/local/lib/python3.10/dist-packages/rclpy/context.py", line 102, in shutdown
    self.__context.shutdown()
rclpy._rclpy_pybind11.RCLError: failed to shutdown: rcl_shutdown already called on the given context, at ./src/rcl/init.c:241
